/Library/Python/3.9/site-packages/urllib3/__init__.py:35: NotOpenSSLWarning: urllib3 v2 only supports OpenSSL 1.1.1+, currently the 'ssl' module is compiled with 'LibreSSL 2.8.3'. See: https://github.com/urllib3/urllib3/issues/3020
  warnings.warn(
Traceback (most recent call last):
  File "/Users/usi/Documents/RealBugsAnalysis/sfdata/runs/s38114534_context.py", line 10, in <module>
    conv = tf.nn.conv2d(
  File "/Library/Python/3.9/site-packages/tensorflow/python/util/traceback_utils.py", line 153, in error_handler
    raise e.with_traceback(filtered_tb) from None
  File "/Library/Python/3.9/site-packages/tensorflow/python/framework/ops.py", line 1021, in _create_c_op
    raise ValueError(e.message)
ValueError: Depth of input (1) is not a multiple of input depth of filter (5) for '{{node conv}} = Conv2D[T=DT_DOUBLE, data_format="NHWC", dilations=[1, 1, 1, 1], explicit_paddings=[], padding="SAME", strides=[1, 1, 1, 1], use_cudnn_on_gpu=true](conv/ReadVariableOp, conv/ReadVariableOp_1)' with input shapes: [1,3,1,1], [1,1,5,1].
