/Library/Python/3.9/site-packages/urllib3/__init__.py:35: NotOpenSSLWarning: urllib3 v2 only supports OpenSSL 1.1.1+, currently the 'ssl' module is compiled with 'LibreSSL 2.8.3'. See: https://github.com/urllib3/urllib3/issues/3020
  warnings.warn(
Traceback (most recent call last):
  File "/Users/usi/Documents/RealBugsAnalysis/sfdata/runs/s41563720_context.py", line 20, in <module>
    model.predict(image)
  File "/Library/Python/3.9/site-packages/keras/src/utils/traceback_utils.py", line 70, in error_handler
    raise e.with_traceback(filtered_tb) from None
  File "/var/folders/gm/btz4l43x3lgg1g9w4c6f4mtc0000gr/T/__autograph_generated_filep8murcz7.py", line 15, in tf__predict_function
    retval_ = ag__.converted_call(ag__.ld(step_function), (ag__.ld(self), ag__.ld(iterator)), None, fscope)
ValueError: in user code:

    File "/Library/Python/3.9/site-packages/keras/src/engine/training.py", line 2416, in predict_function  *
        return step_function(self, iterator)
    File "/Library/Python/3.9/site-packages/keras/src/engine/training.py", line 2401, in step_function  **
        outputs = model.distribute_strategy.run(run_step, args=(data,))
    File "/Library/Python/3.9/site-packages/keras/src/engine/training.py", line 2389, in run_step  **
        outputs = model.predict_step(data)
    File "/Library/Python/3.9/site-packages/keras/src/engine/training.py", line 2357, in predict_step
        return self(x, training=False)
    File "/Library/Python/3.9/site-packages/keras/src/utils/traceback_utils.py", line 70, in error_handler
        raise e.with_traceback(filtered_tb) from None
    File "/Library/Python/3.9/site-packages/keras/src/engine/input_spec.py", line 298, in assert_input_compatibility
        raise ValueError(

    ValueError: Input 0 of layer "sequential" is incompatible with the layer: expected shape=(None, 30, 30, 3), found shape=(None, 30, 3)

