/Library/Python/3.9/site-packages/urllib3/__init__.py:35: NotOpenSSLWarning: urllib3 v2 only supports OpenSSL 1.1.1+, currently the 'ssl' module is compiled with 'LibreSSL 2.8.3'. See: https://github.com/urllib3/urllib3/issues/3020
  warnings.warn(
Traceback (most recent call last):
  File "/Users/usi/Documents/RealBugsAnalysis/sfdata/runs/s55093959_context.py", line 20, in <module>
    env_model.fit(train_x, train_y, epochs=1)
  File "/Library/Python/3.9/site-packages/keras/src/utils/traceback_utils.py", line 70, in error_handler
    raise e.with_traceback(filtered_tb) from None
  File "/var/folders/gm/btz4l43x3lgg1g9w4c6f4mtc0000gr/T/__autograph_generated_file7e2l1cbd.py", line 15, in tf__train_function
    retval_ = ag__.converted_call(ag__.ld(step_function), (ag__.ld(self), ag__.ld(iterator)), None, fscope)
ValueError: in user code:

    File "/Library/Python/3.9/site-packages/keras/src/engine/training.py", line 1377, in train_function  *
        return step_function(self, iterator)
    File "/Library/Python/3.9/site-packages/keras/src/engine/training.py", line 1360, in step_function  **
        outputs = model.distribute_strategy.run(run_step, args=(data,))
    File "/Library/Python/3.9/site-packages/keras/src/engine/training.py", line 1349, in run_step  **
        outputs = model.train_step(data)
    File "/Library/Python/3.9/site-packages/keras/src/engine/training.py", line 1127, in train_step
        loss = self.compute_loss(x, y, y_pred, sample_weight)
    File "/Library/Python/3.9/site-packages/keras/src/engine/training.py", line 1185, in compute_loss
        return self.compiled_loss(
    File "/Library/Python/3.9/site-packages/keras/src/engine/compile_utils.py", line 277, in __call__
        loss_value = loss_obj(y_t, y_p, sample_weight=sw)
    File "/Library/Python/3.9/site-packages/keras/src/losses.py", line 143, in __call__
        losses = call_fn(y_true, y_pred)
    File "/Library/Python/3.9/site-packages/keras/src/losses.py", line 270, in call  **
        return ag_fn(y_true, y_pred, **self._fn_kwargs)
    File "/Library/Python/3.9/site-packages/keras/src/losses.py", line 2221, in categorical_crossentropy
        return backend.categorical_crossentropy(
    File "/Library/Python/3.9/site-packages/keras/src/backend.py", line 5575, in categorical_crossentropy
        target.shape.assert_is_compatible_with(output.shape)

    ValueError: Shapes (None, 1) and (None, 14) are incompatible

