/Library/Python/3.9/site-packages/urllib3/__init__.py:35: NotOpenSSLWarning: urllib3 v2 only supports OpenSSL 1.1.1+, currently the 'ssl' module is compiled with 'LibreSSL 2.8.3'. See: https://github.com/urllib3/urllib3/issues/3020
  warnings.warn(
Traceback (most recent call last):
  File "/Users/usi/Documents/RealBugsAnalysis/sfdata/runs/s55480991_context.py", line 14, in <module>
    units = sess.run(image_in_tf, feed_dict={image_in_tf:image_to_use, keep_prob_tf:1.0})
  File "/Library/Python/3.9/site-packages/tensorflow/python/client/session.py", line 972, in run
    result = self._run(None, fetches, feed_dict, options_ptr,
  File "/Library/Python/3.9/site-packages/tensorflow/python/client/session.py", line 1189, in _run
    raise ValueError(
ValueError: Cannot feed value of shape (128, 128, 3) for Tensor image-in:0, which has shape (None, 128, 128, 3)
