/Library/Python/3.9/site-packages/urllib3/__init__.py:35: NotOpenSSLWarning: urllib3 v2 only supports OpenSSL 1.1.1+, currently the 'ssl' module is compiled with 'LibreSSL 2.8.3'. See: https://github.com/urllib3/urllib3/issues/3020
  warnings.warn(
Traceback (most recent call last):
  File "/Users/usi/Documents/RealBugsAnalysis/sfdata/runs/s63732431_context.py", line 63, in <module>
    model.fit(np.random.rand(100, 48, 48, 1), np.random.rand(100))
  File "/Library/Python/3.9/site-packages/keras/src/utils/traceback_utils.py", line 70, in error_handler
    raise e.with_traceback(filtered_tb) from None
  File "/var/folders/gm/btz4l43x3lgg1g9w4c6f4mtc0000gr/T/__autograph_generated_filetw5525ll.py", line 15, in tf__train_function
    retval_ = ag__.converted_call(ag__.ld(step_function), (ag__.ld(self), ag__.ld(iterator)), None, fscope)
ValueError: in user code:

    File "/Library/Python/3.9/site-packages/keras/src/engine/training.py", line 1377, in train_function  *
        return step_function(self, iterator)
    File "/Library/Python/3.9/site-packages/keras/src/engine/training.py", line 1360, in step_function  **
        outputs = model.distribute_strategy.run(run_step, args=(data,))
    File "/Library/Python/3.9/site-packages/keras/src/engine/training.py", line 1349, in run_step  **
        outputs = model.train_step(data)
    File "/Library/Python/3.9/site-packages/keras/src/engine/training.py", line 1126, in train_step
        y_pred = self(x, training=True)
    File "/Library/Python/3.9/site-packages/keras/src/utils/traceback_utils.py", line 70, in error_handler
        raise e.with_traceback(filtered_tb) from None
    File "/Library/Python/3.9/site-packages/keras/src/engine/input_spec.py", line 298, in assert_input_compatibility
        raise ValueError(

    ValueError: Input 0 of layer "sequential_1" is incompatible with the layer: expected shape=(None, 1, 48, 48, 1), found shape=(None, 48, 48, 1)

