Using TensorFlow backend.
D:\author\RealFaults\bugs\081\buggy\script.py:53: UserWarning: Update your `Conv2D` call to the Keras 2 API: `Conv2D(32, (3, 3), input_shape=(1, 28, 28..., padding="valid")`
  input_shape=(1, img_rows, img_cols)))
2024-07-10 21:51:00.356032: I tensorflow/core/platform/cpu_feature_guard.cc:142] Your CPU supports instructions that this TensorFlow binary was not compiled to use: AVX2
Traceback (most recent call last):
  File "D:\author\RealFaults\RFenv\lib\site-packages\tensorflow_core\python\framework\ops.py", line 1610, in _create_c_op
    c_op = c_api.TF_FinishOperation(op_desc)
tensorflow.python.framework.errors_impl.InvalidArgumentError: Negative dimension size caused by subtracting 3 from 1 for 'conv2d_1/convolution' (op: 'Conv2D') with input shapes: [?,1,28,28], [3,3,28,32].

During handling of the above exception, another exception occurred:

Traceback (most recent call last):
  File "D:\author\RealFaults\bugs\081\buggy\script.py", line 53, in <module>
    input_shape=(1, img_rows, img_cols)))
  File "D:\author\RealFaults\RFenv\lib\site-packages\keras\engine\sequential.py", line 166, in add
    layer(x)
  File "D:\author\RealFaults\RFenv\lib\site-packages\keras\backend\tensorflow_backend.py", line 75, in symbolic_fn_wrapper
    return func(*args, **kwargs)
  File "D:\author\RealFaults\RFenv\lib\site-packages\keras\engine\base_layer.py", line 489, in __call__
    output = self.call(inputs, **kwargs)
  File "D:\author\RealFaults\RFenv\lib\site-packages\keras\layers\convolutional.py", line 171, in call
    dilation_rate=self.dilation_rate)
  File "D:\author\RealFaults\RFenv\lib\site-packages\keras\backend\tensorflow_backend.py", line 3717, in conv2d
    **kwargs)
  File "D:\author\RealFaults\RFenv\lib\site-packages\tensorflow_core\python\ops\nn_ops.py", line 917, in convolution_v2
    name=name)
  File "D:\author\RealFaults\RFenv\lib\site-packages\tensorflow_core\python\ops\nn_ops.py", line 1009, in convolution_internal
    name=name)
  File "D:\author\RealFaults\RFenv\lib\site-packages\tensorflow_core\python\ops\gen_nn_ops.py", line 1070, in conv2d
    data_format=data_format, dilations=dilations, name=name)
  File "D:\author\RealFaults\RFenv\lib\site-packages\tensorflow_core\python\framework\op_def_library.py", line 793, in _apply_op_helper
    op_def=op_def)
  File "D:\author\RealFaults\RFenv\lib\site-packages\tensorflow_core\python\framework\func_graph.py", line 548, in create_op
    compute_device)
  File "D:\author\RealFaults\RFenv\lib\site-packages\tensorflow_core\python\framework\ops.py", line 3429, in _create_op_internal
    op_def=op_def)
  File "D:\author\RealFaults\RFenv\lib\site-packages\tensorflow_core\python\framework\ops.py", line 1773, in __init__
    control_input_ops)
  File "D:\author\RealFaults\RFenv\lib\site-packages\tensorflow_core\python\framework\ops.py", line 1613, in _create_c_op
    raise ValueError(str(e))
ValueError: Negative dimension size caused by subtracting 3 from 1 for 'conv2d_1/convolution' (op: 'Conv2D') with input shapes: [?,1,28,28], [3,3,28,32].
